Workbook

Sheet S1
A1: Reunión semillero 3 a 7 de Agosto del 2026
A2: Nombre del proyecto de investigación | B2: Fecha | C2: Estudiante(s) | D2: Adelantos Realizados | E2: Se Compromete a entrega | F2: Firma de Asistencia | G2: Calificación del Docente | H2: Docente a cargo | I2: Firma Docente
A3: =IFERROR(VLOOKUP(C3,Datos!$U$1:AZ11,2,FALSE),"")
A5: =IFERROR(VLOOKUP(C5,Datos!$U$1:AZ11,2,FALSE),"")
A6: =IFERROR(VLOOKUP(C6,Datos!$U$1:AZ11,2,FALSE),"")
A7: =IFERROR(VLOOKUP(C7,Datos!$U$1:AZ11,2,FALSE),"")
A8: =IFERROR(VLOOKUP(C8,Datos!$U$1:AZ11,2,FALSE),"")
A9: =IFERROR(VLOOKUP(C9,Datos!$U$1:AZ11,2,FALSE),"")
A10: =IFERROR(VLOOKUP(C10,Datos!$U$1:AZ11,2,FALSE),"")
A11: =IFERROR(VLOOKUP(C11,Datos!$U$1:AZ11,2,FALSE),"")

Sheet S2
A1: Reunión semillero 10 a 14 de Agosto del 2026
A2: Nombre del proyecto de investigación | B2: Fecha | C2: Estudiante(s) | D2: Adelantos Realizados | E2: Se Compromete a entrega | F2: Firma de Asistencia | G2: Calificación del Docente | H2: Docente a cargo | I2: Firma Docente
A3: =IFERROR(VLOOKUP(C3,Datos!$U$1:AZ11,2,FALSE),"")
A5: =IFERROR(VLOOKUP(C5,Datos!$U$1:AZ11,2,FALSE),"")
A6: =IFERROR(VLOOKUP(C6,Datos!$U$1:AZ11,2,FALSE),"")
A7: =IFERROR(VLOOKUP(C7,Datos!$U$1:AZ11,2,FALSE),"")
A8: =IFERROR(VLOOKUP(C8,Datos!$U$1:AZ11,2,FALSE),"")
A9: =IFERROR(VLOOKUP(C9,Datos!$U$1:AZ11,2,FALSE),"")
A10: =IFERROR(VLOOKUP(C10,Datos!$U$1:AZ11,2,FALSE),"")
A11: =IFERROR(VLOOKUP(C11,Datos!$U$1:AZ11,2,FALSE),"")

Sheet S3
A1: Reunión semillero 17 a 21 de Agosto del 2026
A2: Nombre del proyecto de investigación | B2: Fecha | C2: Estudiante(s) | D2: Adelantos Realizados | E2: Se Compromete a entrega | F2: Firma de Asistencia | G2: Calificación del Docente | H2: Docente a cargo | I2: Firma Docente
A3: =IFERROR(VLOOKUP(C3,Datos!$U$1:AZ11,2,FALSE),"")
A5: =IFERROR(VLOOKUP(C5,Datos!$U$1:AZ11,2,FALSE),"")
A6: =IFERROR(VLOOKUP(C6,Datos!$U$1:AZ11,2,FALSE),"")
A7: =IFERROR(VLOOKUP(C7,Datos!$U$1:AZ11,2,FALSE),"")
A8: =IFERROR(VLOOKUP(C8,Datos!$U$1:AZ11,2,FALSE),"")
A9: =IFERROR(VLOOKUP(C9,Datos!$U$1:AZ11,2,FALSE),"")
A10: =IFERROR(VLOOKUP(C10,Datos!$U$1:AZ11,2,FALSE),"")
A11: =IFERROR(VLOOKUP(C11,Datos!$U$1:AZ11,2,FALSE),"")

Sheet S4
A1: Reunión semillero 24 a 28 de Agosto del 2026
A2: Nombre del proyecto de investigación | B2: Fecha | C2: Estudiante(s) | D2: Adelantos Realizados | E2: Se Compromete a entrega | F2: Firma de Asistencia | G2: Calificación del Docente | H2: Docente a cargo | I2: Firma Docente
A3: =IFERROR(VLOOKUP(C3,Datos!$U$1:AZ11,2,FALSE),"")
A5: =IFERROR(VLOOKUP(C5,Datos!$U$1:AZ11,2,FALSE),"")
A6: =IFERROR(VLOOKUP(C6,Datos!$U$1:AZ11,2,FALSE),"")
A7: =IFERROR(VLOOKUP(C7,Datos!$U$1:AZ11,2,FALSE),"")
A8: =IFERROR(VLOOKUP(C8,Datos!$U$1:AZ11,2,FALSE),"")
A9: =IFERROR(VLOOKUP(C9,Datos!$U$1:AZ11,2,FALSE),"")
A10: =IFERROR(VLOOKUP(C10,Datos!$U$1:AZ11,2,FALSE),"")
A11: =IFERROR(VLOOKUP(C11,Datos!$U$1:AZ11,2,FALSE),"")

Sheet S5
A1: Reunión semillero 31 de Agosto a 4 de Septiembre del 2026
A2: Nombre del proyecto de investigación | B2: Fecha | C2: Estudiante(s) | D2: Adelantos Realizados | E2: Se Compromete a entrega | F2: Firma de Asistencia | G2: Calificación del Docente | H2: Docente a cargo | I2: Firma Docente
A3: =IFERROR(VLOOKUP(C3,Datos!$U$1:AZ11,2,FALSE),"")
A5: =IFERROR(VLOOKUP(C5,Datos!$U$1:AZ11,2,FALSE),"")
A6: =IFERROR(VLOOKUP(C6,Datos!$U$1:AZ11,2,FALSE),"")
A7: =IFERROR(VLOOKUP(C7,Datos!$U$1:AZ11,2,FALSE),"")
A8: =IFERROR(VLOOKUP(C8,Datos!$U$1:AZ11,2,FALSE),"")
A9: =IFERROR(VLOOKUP(C9,Datos!$U$1:AZ11,2,FALSE),"")
A10: =IFERROR(VLOOKUP(C10,Datos!$U$1:AZ11,2,FALSE),"")
A11: =IFERROR(VLOOKUP(C11,Datos!$U$1:AZ11,2,FALSE),"")

Sheet S6
A1: Reunión semillero 7 a 11 de Septiembre del 2026
A2: Nombre del proyecto de investigación | B2: Fecha | C2: Estudiante(s) | D2: Adelantos Realizados | E2: Se Compromete a entrega | F2: Firma de Asistencia | G2: Calificación del Docente | H2: Docente a cargo | I2: Firma Docente
A3: =IFERROR(VLOOKUP(C3,Datos!$U$1:AZ11,2,FALSE),"")
A5: =IFERROR(VLOOKUP(C5,Datos!$U$1:AZ11,2,FALSE),"")
A6: =IFERROR(VLOOKUP(C6,Datos!$U$1:AZ11,2,FALSE),"")
A7: =IFERROR(VLOOKUP(C7,Datos!$U$1:AZ11,2,FALSE),"")
A8: =IFERROR(VLOOKUP(C8,Datos!$U$1:AZ11,2,FALSE),"")
A9: =IFERROR(VLOOKUP(C9,Datos!$U$1:AZ11,2,FALSE),"")
A10: =IFERROR(VLOOKUP(C10,Datos!$U$1:AZ11,2,FALSE),"")
A11: =IFERROR(VLOOKUP(C11,Datos!$U$1:AZ11,2,FALSE),"")

Sheet S7
A1: Reunión semillero 14 a 18 de Septiembre del 2026
A2: Nombre del proyecto de investigación | B2: Fecha | C2: Estudiante(s) | D2: Adelantos Realizados | E2: Se Compromete a entrega | F2: Firma de Asistencia | G2: Calificación del Docente | H2: Docente a cargo | I2: Firma Docente
A3: =IFERROR(VLOOKUP(C3,Datos!$U$1:AZ11,2,FALSE),"")
A5: =IFERROR(VLOOKUP(C5,Datos!$U$1:AZ11,2,FALSE),"")
A6: =IFERROR(VLOOKUP(C6,Datos!$U$1:AZ11,2,FALSE),"")
A7: =IFERROR(VLOOKUP(C7,Datos!$U$1:AZ11,2,FALSE),"")
A8: =IFERROR(VLOOKUP(C8,Datos!$U$1:AZ11,2,FALSE),"")
A9: =IFERROR(VLOOKUP(C9,Datos!$U$1:AZ11,2,FALSE),"")
A10: =IFERROR(VLOOKUP(C10,Datos!$U$1:AZ11,2,FALSE),"")
A11: =IFERROR(VLOOKUP(C11,Datos!$U$1:AZ11,2,FALSE),"")

Sheet S8
A1: Reunión semillero 21 a 25 de Septiembre del 2026
A2: Nombre del proyecto de investigación | B2: Fecha | C2: Estudiante(s) | D2: Adelantos Realizados | E2: Se Compromete a entrega | F2: Firma de Asistencia | G2: Calificación del Docente | H2: Docente a cargo | I2: Firma Docente
A3: =IFERROR(VLOOKUP(C3,Datos!$U$1:AZ11,2,FALSE),"")
A5: =IFERROR(VLOOKUP(C5,Datos!$U$1:AZ11,2,FALSE),"")
A6: =IFERROR(VLOOKUP(C6,Datos!$U$1:AZ11,2,FALSE),"")
A7: =IFERROR(VLOOKUP(C7,Datos!$U$1:AZ11,2,FALSE),"")
A8: =IFERROR(VLOOKUP(C8,Datos!$U$1:AZ11,2,FALSE),"")
A9: =IFERROR(VLOOKUP(C9,Datos!$U$1:AZ11,2,FALSE),"")
A10: =IFERROR(VLOOKUP(C10,Datos!$U$1:AZ11,2,FALSE),"")
A11: =IFERROR(VLOOKUP(C11,Datos!$U$1:AZ11,2,FALSE),"")

Sheet S9
A1: Reunión semillero 28 de Septiembre a 2 de Octubre del 2026
A2: Nombre del proyecto de investigación | B2: Fecha | C2: Estudiante(s) | D2: Adelantos Realizados | E2: Se Compromete a entrega | F2: Firma de Asistencia | G2: Calificación del Docente | H2: Docente a cargo | I2: Firma Docente
A3: =IFERROR(VLOOKUP(C3,Datos!$U$1:AZ11,2,FALSE),"")
A5: =IFERROR(VLOOKUP(C5,Datos!$U$1:AZ11,2,FALSE),"")
A6: =IFERROR(VLOOKUP(C6,Datos!$U$1:AZ11,2,FALSE),"")
A7: =IFERROR(VLOOKUP(C7,Datos!$U$1:AZ11,2,FALSE),"")
A8: =IFERROR(VLOOKUP(C8,Datos!$U$1:AZ11,2,FALSE),"")
A9: =IFERROR(VLOOKUP(C9,Datos!$U$1:AZ11,2,FALSE),"")
A10: =IFERROR(VLOOKUP(C10,Datos!$U$1:AZ11,2,FALSE),"")
A11: =IFERROR(VLOOKUP(C11,Datos!$U$1:AZ11,2,FALSE),"")

Sheet S10
A1: Reunión semillero 5 a 9 de Octubre del 2026
A2: Nombre del proyecto de investigación | B2: Fecha | C2: Estudiante(s) | D2: Adelantos Realizados | E2: Se Compromete a entrega | F2: Firma de Asistencia | G2: Calificación del Docente | H2: Docente a cargo | I2: Firma Docente
A3: =IFERROR(VLOOKUP(C3,Datos!$U$1:AZ11,2,FALSE),"")
A5: =IFERROR(VLOOKUP(C5,Datos!$U$1:AZ11,2,FALSE),"")
A6: =IFERROR(VLOOKUP(C6,Datos!$U$1:AZ11,2,FALSE),"")
A7: =IFERROR(VLOOKUP(C7,Datos!$U$1:AZ11,2,FALSE),"")
A8: =IFERROR(VLOOKUP(C8,Datos!$U$1:AZ11,2,FALSE),"")
A9: =IFERROR(VLOOKUP(C9,Datos!$U$1:AZ11,2,FALSE),"")
A10: =IFERROR(VLOOKUP(C10,Datos!$U$1:AZ11,2,FALSE),"")
A11: =IFERROR(VLOOKUP(C11,Datos!$U$1:AZ11,2,FALSE),"")

Sheet S11
A1: Reunión semillero 12 a 16 de Octubre del 2026
A2: Nombre del proyecto de investigación | B2: Fecha | C2: Estudiante(s) | D2: Adelantos Realizados | E2: Se Compromete a entrega | F2: Firma de Asistencia | G2: Calificación del Docente | H2: Docente a cargo | I2: Firma Docente
A3: =IFERROR(VLOOKUP(C3,Datos!$U$1:AZ11,2,FALSE),"")
A5: =IFERROR(VLOOKUP(C5,Datos!$U$1:AZ11,2,FALSE),"")
A6: =IFERROR(VLOOKUP(C6,Datos!$U$1:AZ11,2,FALSE),"")
A7: =IFERROR(VLOOKUP(C7,Datos!$U$1:AZ11,2,FALSE),"")
A8: =IFERROR(VLOOKUP(C8,Datos!$U$1:AZ11,2,FALSE),"")
A9: =IFERROR(VLOOKUP(C9,Datos!$U$1:AZ11,2,FALSE),"")
A10: =IFERROR(VLOOKUP(C10,Datos!$U$1:AZ11,2,FALSE),"")
A11: =IFERROR(VLOOKUP(C11,Datos!$U$1:AZ11,2,FALSE),"")

Sheet S12
A1: Reunión semillero 19 a 23 de Octubre del 2026
A2: Nombre del proyecto de investigación | B2: Fecha | C2: Estudiante(s) | D2: Adelantos Realizados | E2: Se Compromete a entrega | F2: Firma de Asistencia | G2: Calificación del Docente | H2: Docente a cargo | I2: Firma Docente
A3: =IFERROR(VLOOKUP(C3,Datos!$U$1:AZ11,2,FALSE),"")
A5: =IFERROR(VLOOKUP(C5,Datos!$U$1:AZ11,2,FALSE),"")
A6: =IFERROR(VLOOKUP(C6,Datos!$U$1:AZ11,2,FALSE),"")
A7: =IFERROR(VLOOKUP(C7,Datos!$U$1:AZ11,2,FALSE),"")
A8: =IFERROR(VLOOKUP(C8,Datos!$U$1:AZ11,2,FALSE),"")
A9: =IFERROR(VLOOKUP(C9,Datos!$U$1:AZ11,2,FALSE),"")
A10: =IFERROR(VLOOKUP(C10,Datos!$U$1:AZ11,2,FALSE),"")
A11: =IFERROR(VLOOKUP(C11,Datos!$U$1:AZ11,2,FALSE),"")

Sheet S13
A1: Reunión semillero 26 a 30 de Octubre del 2026
A2: Nombre del proyecto de investigación | B2: Fecha | C2: Estudiante(s) | D2: Adelantos Realizados | E2: Se Compromete a entrega | F2: Firma de Asistencia | G2: Calificación del Docente | H2: Docente a cargo | I2: Firma Docente
A3: =IFERROR(VLOOKUP(C3,Datos!$U$1:AZ11,2,FALSE),"")
A5: =IFERROR(VLOOKUP(C5,Datos!$U$1:AZ11,2,FALSE),"")
A6: =IFERROR(VLOOKUP(C6,Datos!$U$1:AZ11,2,FALSE),"")
A7: =IFERROR(VLOOKUP(C7,Datos!$U$1:AZ11,2,FALSE),"")
A8: =IFERROR(VLOOKUP(C8,Datos!$U$1:AZ11,2,FALSE),"")
A9: =IFERROR(VLOOKUP(C9,Datos!$U$1:AZ11,2,FALSE),"")
A10: =IFERROR(VLOOKUP(C10,Datos!$U$1:AZ11,2,FALSE),"")
A11: =IFERROR(VLOOKUP(C11,Datos!$U$1:AZ11,2,FALSE),"")

Sheet S14
A1: Reunión semillero 2 a 6 de Noviembre del 2026
A2: Nombre del proyecto de investigación | B2: Fecha | C2: Estudiante(s) | D2: Adelantos Realizados | E2: Se Compromete a entrega | F2: Firma de Asistencia | G2: Calificación del Docente | H2: Docente a cargo | I2: Firma Docente
A3: =IFERROR(VLOOKUP(C3,Datos!$U$1:AZ11,2,FALSE),"")
A5: =IFERROR(VLOOKUP(C5,Datos!$U$1:AZ11,2,FALSE),"")
A6: =IFERROR(VLOOKUP(C6,Datos!$U$1:AZ11,2,FALSE),"")
A7: =IFERROR(VLOOKUP(C7,Datos!$U$1:AZ11,2,FALSE),"")
A8: =IFERROR(VLOOKUP(C8,Datos!$U$1:AZ11,2,FALSE),"")
A9: =IFERROR(VLOOKUP(C9,Datos!$U$1:AZ11,2,FALSE),"")
A10: =IFERROR(VLOOKUP(C10,Datos!$U$1:AZ11,2,FALSE),"")
A11: =IFERROR(VLOOKUP(C11,Datos!$U$1:AZ11,2,FALSE),"")

Sheet S15
A1: Reunión semillero 9 a 13 de Noviembre del 2026
A2: Nombre del proyecto de investigación | B2: Fecha | C2: Estudiante(s) | D2: Adelantos Realizados | E2: Se Compromete a entrega | F2: Firma de Asistencia | G2: Calificación del Docente | H2: Docente a cargo | I2: Firma Docente
A3: =IFERROR(VLOOKUP(C3,Datos!$U$1:AZ11,2,FALSE),"")
A5: =IFERROR(VLOOKUP(C5,Datos!$U$1:AZ11,2,FALSE),"")
A6: =IFERROR(VLOOKUP(C6,Datos!$U$1:AZ11,2,FALSE),"")
A7: =IFERROR(VLOOKUP(C7,Datos!$U$1:AZ11,2,FALSE),"")
A8: =IFERROR(VLOOKUP(C8,Datos!$U$1:AZ11,2,FALSE),"")
A9: =IFERROR(VLOOKUP(C9,Datos!$U$1:AZ11,2,FALSE),"")
A10: =IFERROR(VLOOKUP(C10,Datos!$U$1:AZ11,2,FALSE),"")
A11: =IFERROR(VLOOKUP(C11,Datos!$U$1:AZ11,2,FALSE),"")

Sheet S16
A1: Reunión semillero 16 a 20 de Noviembre del 2026
A2: Nombre del proyecto de investigación | B2: Fecha | C2: Estudiante(s) | D2: Adelantos Realizados | E2: Se Compromete a entrega | F2: Firma de Asistencia | G2: Calificación del Docente | H2: Docente a cargo | I2: Firma Docente
A3: =IFERROR(VLOOKUP(C3,Datos!$U$1:AZ11,2,FALSE),"")
A5: =IFERROR(VLOOKUP(C5,Datos!$U$1:AZ11,2,FALSE),"")
A6: =IFERROR(VLOOKUP(C6,Datos!$U$1:AZ11,2,FALSE),"")
A7: =IFERROR(VLOOKUP(C7,Datos!$U$1:AZ11,2,FALSE),"")
A8: =IFERROR(VLOOKUP(C8,Datos!$U$1:AZ11,2,FALSE),"")
A9: =IFERROR(VLOOKUP(C9,Datos!$U$1:AZ11,2,FALSE),"")
A10: =IFERROR(VLOOKUP(C10,Datos!$U$1:AZ11,2,FALSE),"")
A11: =IFERROR(VLOOKUP(C11,Datos!$U$1:AZ11,2,FALSE),"")

Sheet Datos
A1: 2026-20 | B1: #S | C1: ASIST | D1: PROM | E1: S1 | F1: S2 | G1: S3 | H1: S4 | I1: S5 | J1: S6 | K1: S7 | L1: S8 | M1: S9 | N1: S10 | O1: S11 | P1: S12 | Q1: S13 | R1: S14 | S1: S15 | T1: S16 | U1: =IFERROR(__xludf.DUMMYFUNCTION("IMPORTRANGE(""https://docs.google.com/spreadsheets/d/1R1q_v9cqxB9XzYyWQGm80bkEILZdpNVMnTxyGhN_sSg/edit?gid=904666944#gid=904666944"",""'Datos2'!A:Z"")"),"Estudiante") -> Estudiante | V1: =IFERROR(__xludf.DUMMYFUNCTION("""COMPUTED_VALUE"""),"Proyecto") -> Proyecto | W1: =IFERROR(__xludf.DUMMYFUNCTION("""COMPUTED_VALUE"""),"2025-10") -> 2025-10 | X1: =IFERROR(__xludf.DUMMYFUNCTION("""COMPUTED_VALUE"""),"2025-20") -> 2025-20 | Y1: =IFERROR(__xludf.DUMMYFUNCTION("""COMPUTED_VALUE"""),"2026-10") -> 2026-10 | Z1: =IFERROR(__xludf.DUMMYFUNCTION("""COMPUTED_VALUE"""),"2026-20") -> 2026-20 | AA1: =IFERROR(__xludf.DUMMYFUNCTION("""COMPUTED_VALUE"""),"2027-10") -> 2027-10 | AB1: =IFERROR(__xludf.DUMMYFUNCTION("""COMPUTED_VALUE"""),"2027-20") -> 2027-20 | AC1: =IFERROR(__xludf.DUMMYFUNCTION("""COMPUTED_VALUE"""),"2028-10") -> 2028-10 | AD1: =IFERROR(__xludf.DUMMYFUNCTION("""COMPUTED_VALUE"""),"2028-20") -> 2028-20 | AE1: =IFERROR(__xludf.DUMMYFUNCTION("""COMPUTED_VALUE"""),"2029-10") -> 2029-10 | AF1: =IFERROR(__xludf.DUMMYFUNCTION("""COMPUTED_VALUE"""),"2029-20") -> 2029-20 | AG1: =IFERROR(__xludf.DUMMYFUNCTION("""COMPUTED_VALUE"""),"2030-10") -> 2030-10 | AH1: =IFERROR(__xludf.DUMMYFUNCTION("""COMPUTED_VALUE"""),"2030-20") -> 2030-20 | AI1: =IFERROR(__xludf.DUMMYFUNCTION("""COMPUTED_VALUE"""),"2031-10") -> 2031-10 | AJ1: =IFERROR(__xludf.DUMMYFUNCTION("""COMPUTED_VALUE"""),"2031-20") -> 2031-20 | AK1: =IFERROR(__xludf.DUMMYFUNCTION("""COMPUTED_VALUE"""),"2032-10") -> 2032-10 | AL1: =IFERROR(__xludf.DUMMYFUNCTION("""COMPUTED_VALUE"""),"2032-20") -> 2032-20 | AM1: =IFERROR(__xludf.DUMMYFUNCTION("""COMPUTED_VALUE"""),"2033-10") -> 2033-10 | AN1: =IFERROR(__xludf.DUMMYFUNCTION("""COMPUTED_VALUE"""),"2033-20") -> 2033-20 | AO1: =IFERROR(__xludf.DUMMYFUNCTION("""COMPUTED_VALUE"""),"2034-10") -> 2034-10 | AP1: =IFERROR(__xludf.DUMMYFUNCTION("""COMPUTED_VALUE"""),"2034-20") -> 2034-20 | AQ1: =IFERROR(__xludf.DUMMYFUNCTION("""COMPUTED_VALUE"""),"2035-10") -> 2035-10 | AR1: =IFERROR(__xludf.DUMMYFUNCTION("""COMPUTED_VALUE"""),"2035-20") -> 2035-20 | AS1: =IFERROR(__xludf.DUMMYFUNCTION("""COMPUTED_VALUE"""),"2036-10") -> 2036-10 | AT1: =IFERROR(__xludf.DUMMYFUNCTION("""COMPUTED_VALUE"""),"2036-20") -> 2036-20
A2: =IFERROR(__xludf.DUMMYFUNCTION("FILTER( U2:U1500, INDEX(W2:ZZ1500, 0, MATCH(A1, W1:ZZ1, 0))=""X"" )"),"Angy Juliana Farasica") -> Angy Juliana Farasica | C2: =IF(B2="","",COUNT(E2:T2)) | D2: =IFERROR(SUM(E2:T2)/B2,"") | E2: =IFERROR(VLOOKUP($A2,INDIRECT("'" & E$1 & "'!$C:$G"), 5, FALSE),"") | F2: =IFERROR(VLOOKUP($A2,INDIRECT("'" & F$1 & "'!$C:$G"), 5, FALSE),"") | G2: =IFERROR(VLOOKUP($A2,INDIRECT("'" & G$1 & "'!$C:$G"), 5, FALSE),"") | H2: =IFERROR(VLOOKUP($A2,INDIRECT("'" & H$1 & "'!$C:$G"), 5, FALSE),"") | I2: =IFERROR(VLOOKUP($A2,INDIRECT("'" & I$1 & "'!$C:$G"), 5, FALSE),"") | J2: =IFERROR(VLOOKUP($A2,INDIRECT("'" & J$1 & "'!$C:$G"), 5, FALSE),"") | K2: =IFERROR(VLOOKUP($A2,INDIRECT("'" & K$1 & "'!$C:$G"), 5, FALSE),"") | L2: =IFERROR(VLOOKUP($A2,INDIRECT("'" & L$1 & "'!$C:$G"), 5, FALSE),"") | ... T2: =IFERROR(VLOOKUP($A2,INDIRECT("'" & T$1 & "'!$C:$G"), 5, FALSE),"") | U2: =IFERROR(__xludf.DUMMYFUNCTION("""COMPUTED_VALUE"""),"Angy Juliana Farasica") -> Angy Juliana Farasica | V2: =IFERROR(__xludf.DUMMYFUNCTION("""COMPUTED_VALUE"""),"Aplicativo móvil con realidad aumentada para la práctica y adquisición de vocabulario de inglés a nivel A1") -> Aplicativo móvil con realidad aumentada para la práctica y adquisición de vocabulario de inglés a nivel A1 | W2: =IFERROR(__xludf.DUMMYFUNCTION("""COMPUTED_VALUE"""),"") | X2: =IFERROR(__xludf.DUMMYFUNCTION("""COMPUTED_VALUE"""),"X") -> X | Y2: =IFERROR(__xludf.DUMMYFUNCTION("""COMPUTED_VALUE"""),"X") -> X | Z2: =IFERROR(__xludf.DUMMYFUNCTION("""COMPUTED_VALUE"""),"X") -> X | AA2: =IFERROR(__xludf.DUMMYFUNCTION("""COMPUTED_VALUE"""),"") | AB2: =IFERROR(__xludf.DUMMYFUNCTION("""COMPUTED_VALUE"""),"") | AC2: =IFERROR(__xludf.DUMMYFUNCTION("""COMPUTED_VALUE"""),"") | AD2: =IFERROR(__xludf.DUMMYFUNCTION("""COMPUTED_VALUE"""),"") | AE2: =IFERROR(__xludf.DUMMYFUNCTION("""COMPUTED_VALUE"""),"") | AF2: =IFERROR(__xludf.DUMMYFUNCTION("""COMPUTED_VALUE"""),"") | AG2: =IFERROR(__xludf.DUMMYFUNCTION("""COMPUTED_VALUE"""),"") | AH2: =IFERROR(__xludf.DUMMYFUNCTION("""COMPUTED_VALUE"""),"") | ... AT2: =IFERROR(__xludf.DUMMYFUNCTION("""COMPUTED_VALUE"""),"")
A3: =IFERROR(__xludf.DUMMYFUNCTION("""COMPUTED_VALUE"""),"Daniel Alejandro Rodríguez") -> Daniel Alejandro Rodríguez | C3: =IF(B3="","",COUNT(E3:T3)) | D3: =IFERROR(SUM(E3:T3)/B3,"") | E3: =IFERROR(VLOOKUP($A3,INDIRECT("'" & E$1 & "'!$C:$G"), 5, FALSE),"") | F3: =IFERROR(VLOOKUP($A3,INDIRECT("'" & F$1 & "'!$C:$G"), 5, FALSE),"") | G3: =IFERROR(VLOOKUP($A3,INDIRECT("'" & G$1 & "'!$C:$G"), 5, FALSE),"") | H3: =IFERROR(VLOOKUP($A3,INDIRECT("'" & H$1 & "'!$C:$G"), 5, FALSE),"") | I3: =IFERROR(VLOOKUP($A3,INDIRECT("'" & I$1 & "'!$C:$G"), 5, FALSE),"") | J3: =IFERROR(VLOOKUP($A3,INDIRECT("'" & J$1 & "'!$C:$G"), 5, FALSE),"") | K3: =IFERROR(VLOOKUP($A3,INDIRECT("'" & K$1 & "'!$C:$G"), 5, FALSE),"") | L3: =IFERROR(VLOOKUP($A3,INDIRECT("'" & L$1 & "'!$C:$G"), 5, FALSE),"") | ... T3: =IFERROR(VLOOKUP($A3,INDIRECT("'" & T$1 & "'!$C:$G"), 5, FALSE),"") | U3: =IFERROR(__xludf.DUMMYFUNCTION("""COMPUTED_VALUE"""),"Daniel Alejandro Rodríguez") -> Daniel Alejandro Rodríguez | V3: =IFERROR(__xludf.DUMMYFUNCTION("""COMPUTED_VALUE"""),"Aplicativo móvil con realidad aumentada para la comprensión de las métricas y proporciones en el dibujo anatómico") -> Aplicativo móvil con realidad aumentada para la comprensión de las métricas y proporciones en el dibujo anatómico | W3: =IFERROR(__xludf.DUMMYFUNCTION("""COMPUTED_VALUE"""),"") | X3: =IFERROR(__xludf.DUMMYFUNCTION("""COMPUTED_VALUE"""),"X") -> X | Y3: =IFERROR(__xludf.DUMMYFUNCTION("""COMPUTED_VALUE"""),"X") -> X | Z3: =IFERROR(__xludf.DUMMYFUNCTION("""COMPUTED_VALUE"""),"X") -> X | AA3: =IFERROR(__xludf.DUMMYFUNCTION("""COMPUTED_VALUE"""),"") | AB3: =IFERROR(__xludf.DUMMYFUNCTION("""COMPUTED_VALUE"""),"") | AC3: =IFERROR(__xludf.DUMMYFUNCTION("""COMPUTED_VALUE"""),"") | AD3: =IFERROR(__xludf.DUMMYFUNCTION("""COMPUTED_VALUE"""),"")
A4: =IFERROR(__xludf.DUMMYFUNCTION("""COMPUTED_VALUE"""),"Sara Sofia Moreno Castro") -> Sara Sofia Moreno Castro | C4: =IF(B4="","",COUNT(E4:T4)) | D4: =IFERROR(SUM(E4:T4)/B4,"") | E4: =IFERROR(VLOOKUP($A4,INDIRECT("'" & E$1 & "'!$C:$G"), 5, FALSE),"") | F4: =IFERROR(VLOOKUP($A4,INDIRECT("'" & F$1 & "'!$C:$G"), 5, FALSE),"") | G4: =IFERROR(VLOOKUP($A4,INDIRECT("'" & G$1 & "'!$C:$G"), 5, FALSE),"") | H4: =IFERROR(VLOOKUP($A4,INDIRECT("'" & H$1 & "'!$C:$G"), 5, FALSE),"") | I4: =IFERROR(VLOOKUP($A4,INDIRECT("'" & I$1 & "'!$C:$G"), 5, FALSE),"") | J4: =IFERROR(VLOOKUP($A4,INDIRECT("'" & J$1 & "'!$C:$G"), 5, FALSE),"") | K4: =IFERROR(VLOOKUP($A4,INDIRECT("'" & K$1 & "'!$C:$G"), 5, FALSE),"") | L4: =IFERROR(VLOOKUP($A4,INDIRECT("'" & L$1 & "'!$C:$G"), 5, FALSE),"") | ... T4: =IFERROR(VLOOKUP($A4,INDIRECT("'" & T$1 & "'!$C:$G"), 5, FALSE),"") | U4: =IFERROR(__xludf.DUMMYFUNCTION("""COMPUTED_VALUE"""),"Sara Sofia Moreno Castro") -> Sara Sofia Moreno Castro | V4: =IFERROR(__xludf.DUMMYFUNCTION("""COMPUTED_VALUE"""),"Libro Interactivo para la Divulgación del Programa de Ingeniería en Multimedia de la Universidad de Boyacá") -> Libro Interactivo para la Divulgación del Programa de Ingeniería en Multimedia de la Universidad de Boyacá | W4: =IFERROR(__xludf.DUMMYFUNCTION("""COMPUTED_VALUE"""),"") | X4: =IFERROR(__xludf.DUMMYFUNCTION("""COMPUTED_VALUE"""),"X") -> X | Y4: =IFERROR(__xludf.DUMMYFUNCTION("""COMPUTED_VALUE"""),"X") -> X | Z4: =IFERROR(__xludf.DUMMYFUNCTION("""COMPUTED_VALUE"""),"X") -> X | AA4: =IFERROR(__xludf.DUMMYFUNCTION("""COMPUTED_VALUE"""),"") | AB4: =IFERROR(__xludf.DUMMYFUNCTION("""COMPUTED_VALUE"""),"") | AC4: =IFERROR(__xludf.DUMMYFUNCTION("""COMPUTED_VALUE"""),"") | AD4: =IFERROR(__xludf.DUMMYFUNCTION("""COMPUTED_VALUE"""),"")
A5: =IFERROR(__xludf.DUMMYFUNCTION("""COMPUTED_VALUE"""),"David Santiago Amaya Reyes") -> David Santiago Amaya Reyes | C5: =IF(B5="","",COUNT(E5:T5)) | D5: =IFERROR(SUM(E5:T5)/B5,"") | E5: =IFERROR(VLOOKUP($A5,INDIRECT("'" & E$1 & "'!$C:$G"), 5, FALSE),"") | F5: =IFERROR(VLOOKUP($A5,INDIRECT("'" & F$1 & "'!$C:$G"), 5, FALSE),"") | G5: =IFERROR(VLOOKUP($A5,INDIRECT("'" & G$1 & "'!$C:$G"), 5, FALSE),"") | H5: =IFERROR(VLOOKUP($A5,INDIRECT("'" & H$1 & "'!$C:$G"), 5, FALSE),"") | I5: =IFERROR(VLOOKUP($A5,INDIRECT("'" & I$1 & "'!$C:$G"), 5, FALSE),"") | J5: =IFERROR(VLOOKUP($A5,INDIRECT("'" & J$1 & "'!$C:$G"), 5, FALSE),"") | K5: =IFERROR(VLOOKUP($A5,INDIRECT("'" & K$1 & "'!$C:$G"), 5, FALSE),"") | L5: =IFERROR(VLOOKUP($A5,INDIRECT("'" & L$1 & "'!$C:$G"), 5, FALSE),"") | ... T5: =IFERROR(VLOOKUP($A5,INDIRECT("'" & T$1 & "'!$C:$G"), 5, FALSE),"") | U5: =IFERROR(__xludf.DUMMYFUNCTION("""COMPUTED_VALUE"""),"David Santiago Amaya Reyes") -> David Santiago Amaya Reyes | V5: =IFERROR(__xludf.DUMMYFUNCTION("""COMPUTED_VALUE"""),"Narrativa Web Interactiva para Divulgar la Historia de la Batalla del Pantano de Vargas, Paipa") -> Narrativa Web Interactiva para Divulgar la Historia de la Batalla del Pantano de Vargas, Paipa | W5: =IFERROR(__xludf.DUMMYFUNCTION("""COMPUTED_VALUE"""),"") | X5: =IFERROR(__xludf.DUMMYFUNCTION("""COMPUTED_VALUE"""),"X") -> X | Y5: =IFERROR(__xludf.DUMMYFUNCTION("""COMPUTED_VALUE"""),"X") -> X | Z5: =IFERROR(__xludf.DUMMYFUNCTION("""COMPUTED_VALUE"""),"X") -> X | AA5: =IFERROR(__xludf.DUMMYFUNCTION("""COMPUTED_VALUE"""),"") | AB5: =IFERROR(__xludf.DUMMYFUNCTION("""COMPUTED_VALUE"""),"") | AC5: =IFERROR(__xludf.DUMMYFUNCTION("""COMPUTED_VALUE"""),"") | AD5: =IFERROR(__xludf.DUMMYFUNCTION("""COMPUTED_VALUE"""),"")
A6: =IFERROR(__xludf.DUMMYFUNCTION("""COMPUTED_VALUE"""),"Daniel Felipe Sainea") -> Daniel Felipe Sainea | C6: =IF(B6="","",COUNT(E6:T6)) | D6: =IFERROR(SUM(E6:T6)/B6,"") | E6: =IFERROR(VLOOKUP($A6,INDIRECT("'" & E$1 & "'!$C:$G"), 5, FALSE),"") | F6: =IFERROR(VLOOKUP($A6,INDIRECT("'" & F$1 & "'!$C:$G"), 5, FALSE),"") | G6: =IFERROR(VLOOKUP($A6,INDIRECT("'" & G$1 & "'!$C:$G"), 5, FALSE),"") | H6: =IFERROR(VLOOKUP($A6,INDIRECT("'" & H$1 & "'!$C:$G"), 5, FALSE),"") | I6: =IFERROR(VLOOKUP($A6,INDIRECT("'" & I$1 & "'!$C:$G"), 5, FALSE),"") | J6: =IFERROR(VLOOKUP($A6,INDIRECT("'" & J$1 & "'!$C:$G"), 5, FALSE),"") | K6: =IFERROR(VLOOKUP($A6,INDIRECT("'" & K$1 & "'!$C:$G"), 5, FALSE),"") | L6: =IFERROR(VLOOKUP($A6,INDIRECT("'" & L$1 & "'!$C:$G"), 5, FALSE),"") | ... T6: =IFERROR(VLOOKUP($A6,INDIRECT("'" & T$1 & "'!$C:$G"), 5, FALSE),"") | U6: =IFERROR(__xludf.DUMMYFUNCTION("""COMPUTED_VALUE"""),"Daniel Felipe Sainea") -> Daniel Felipe Sainea | V6: =IFERROR(__xludf.DUMMYFUNCTION("""COMPUTED_VALUE"""),"Recorrido virtual interactivo del edificio 4 de la Universidad de Boyacá") -> Recorrido virtual interactivo del edificio 4 de la Universidad de Boyacá | W6: =IFERROR(__xludf.DUMMYFUNCTION("""COMPUTED_VALUE"""),"") | X6: =IFERROR(__xludf.DUMMYFUNCTION("""COMPUTED_VALUE"""),"X") -> X | Y6: =IFERROR(__xludf.DUMMYFUNCTION("""COMPUTED_VALUE"""),"X") -> X | Z6: =IFERROR(__xludf.DUMMYFUNCTION("""COMPUTED_VALUE"""),"X") -> X | AA6: =IFERROR(__xludf.DUMMYFUNCTION("""COMPUTED_VALUE"""),"") | AB6: =IFERROR(__xludf.DUMMYFUNCTION("""COMPUTED_VALUE"""),"") | AC6: =IFERROR(__xludf.DUMMYFUNCTION("""COMPUTED_VALUE"""),"") | AD6: =IFERROR(__xludf.DUMMYFUNCTION("""COMPUTED_VALUE"""),"")
A7: =IFERROR(__xludf.DUMMYFUNCTION("""COMPUTED_VALUE"""),"Diana Sofia Benavides Monroy") -> Diana Sofia Benavides Monroy | C7: =IF(B7="","",COUNT(E7:T7)) | D7: =IFERROR(SUM(E7:T7)/B7,"") | E7: =IFERROR(VLOOKUP($A7,INDIRECT("'" & E$1 & "'!$C:$G"), 5, FALSE),"") | F7: =IFERROR(VLOOKUP($A7,INDIRECT("'" & F$1 & "'!$C:$G"), 5, FALSE),"") | G7: =IFERROR(VLOOKUP($A7,INDIRECT("'" & G$1 & "'!$C:$G"), 5, FALSE),"") | H7: =IFERROR(VLOOKUP($A7,INDIRECT("'" & H$1 & "'!$C:$G"), 5, FALSE),"") | I7: =IFERROR(VLOOKUP($A7,INDIRECT("'" & I$1 & "'!$C:$G"), 5, FALSE),"") | J7: =IFERROR(VLOOKUP($A7,INDIRECT("'" & J$1 & "'!$C:$G"), 5, FALSE),"") | K7: =IFERROR(VLOOKUP($A7,INDIRECT("'" & K$1 & "'!$C:$G"), 5, FALSE),"") | L7: =IFERROR(VLOOKUP($A7,INDIRECT("'" & L$1 & "'!$C:$G"), 5, FALSE),"") | ... T7: =IFERROR(VLOOKUP($A7,INDIRECT("'" & T$1 & "'!$C:$G"), 5, FALSE),"") | U7: =IFERROR(__xludf.DUMMYFUNCTION("""COMPUTED_VALUE"""),"Diana Sofia Benavides Monroy") -> Diana Sofia Benavides Monroy | V7: =IFERROR(__xludf.DUMMYFUNCTION("""COMPUTED_VALUE"""),"Videojuego 2D para apoyar competencias matemáticas básicas de números enteros en niños") -> Videojuego 2D para apoyar competencias matemáticas básicas de números enteros en niños | W7: =IFERROR(__xludf.DUMMYFUNCTION("""COMPUTED_VALUE"""),"") | X7: =IFERROR(__xludf.DUMMYFUNCTION("""COMPUTED_VALUE"""),"X") -> X | Y7: =IFERROR(__xludf.DUMMYFUNCTION("""COMPUTED_VALUE"""),"X") -> X | Z7: =IFERROR(__xludf.DUMMYFUNCTION("""COMPUTED_VALUE"""),"X") -> X | AA7: =IFERROR(__xludf.DUMMYFUNCTION("""COMPUTED_VALUE"""),"") | AB7: =IFERROR(__xludf.DUMMYFUNCTION("""COMPUTED_VALUE"""),"") | AC7: =IFERROR(__xludf.DUMMYFUNCTION("""COMPUTED_VALUE"""),"") | AD7: =IFERROR(__xludf.DUMMYFUNCTION("""COMPUTED_VALUE"""),"")
A8: =IFERROR(__xludf.DUMMYFUNCTION("""COMPUTED_VALUE"""),"David Alejandro Gonzalez") -> David Alejandro Gonzalez | C8: =IF(B8="","",COUNT(E8:T8)) | D8: =IFERROR(SUM(E8:T8)/B8,"") | E8: =IFERROR(VLOOKUP($A8,INDIRECT("'" & E$1 & "'!$C:$G"), 5, FALSE),"") | F8: =IFERROR(VLOOKUP($A8,INDIRECT("'" & F$1 & "'!$C:$G"), 5, FALSE),"") | G8: =IFERROR(VLOOKUP($A8,INDIRECT("'" & G$1 & "'!$C:$G"), 5, FALSE),"") | H8: =IFERROR(VLOOKUP($A8,INDIRECT("'" & H$1 & "'!$C:$G"), 5, FALSE),"") | I8: =IFERROR(VLOOKUP($A8,INDIRECT("'" & I$1 & "'!$C:$G"), 5, FALSE),"") | J8: =IFERROR(VLOOKUP($A8,INDIRECT("'" & J$1 & "'!$C:$G"), 5, FALSE),"") | K8: =IFERROR(VLOOKUP($A8,INDIRECT("'" & K$1 & "'!$C:$G"), 5, FALSE),"") | L8: =IFERROR(VLOOKUP($A8,INDIRECT("'" & L$1 & "'!$C:$G"), 5, FALSE),"") | ... T8: =IFERROR(VLOOKUP($A8,INDIRECT("'" & T$1 & "'!$C:$G"), 5, FALSE),"") | U8: =IFERROR(__xludf.DUMMYFUNCTION("""COMPUTED_VALUE"""),"David Alejandro Gonzalez") -> David Alejandro Gonzalez | W8: =IFERROR(__xludf.DUMMYFUNCTION("""COMPUTED_VALUE"""),"") | X8: =IFERROR(__xludf.DUMMYFUNCTION("""COMPUTED_VALUE"""),"X") -> X | Y8: =IFERROR(__xludf.DUMMYFUNCTION("""COMPUTED_VALUE"""),"X") -> X | Z8: =IFERROR(__xludf.DUMMYFUNCTION("""COMPUTED_VALUE"""),"X") -> X | AA8: =IFERROR(__xludf.DUMMYFUNCTION("""COMPUTED_VALUE"""),"") | AB8: =IFERROR(__xludf.DUMMYFUNCTION("""COMPUTED_VALUE"""),"") | AC8: =IFERROR(__xludf.DUMMYFUNCTION("""COMPUTED_VALUE"""),"") | AD8: =IFERROR(__xludf.DUMMYFUNCTION("""COMPUTED_VALUE"""),"")
A9: =IFERROR(__xludf.DUMMYFUNCTION("""COMPUTED_VALUE"""),"Hugo Alexander Fonseca Chaparro") -> Hugo Alexander Fonseca Chaparro | C9: =IF(B9="","",COUNT(E9:T9)) | D9: =IFERROR(SUM(E9:T9)/B9,"") | E9: =IFERROR(VLOOKUP($A9,INDIRECT("'" & E$1 & "'!$C:$G"), 5, FALSE),"") | F9: =IFERROR(VLOOKUP($A9,INDIRECT("'" & F$1 & "'!$C:$G"), 5, FALSE),"") | G9: =IFERROR(VLOOKUP($A9,INDIRECT("'" & G$1 & "'!$C:$G"), 5, FALSE),"") | H9: =IFERROR(VLOOKUP($A9,INDIRECT("'" & H$1 & "'!$C:$G"), 5, FALSE),"") | I9: =IFERROR(VLOOKUP($A9,INDIRECT("'" & I$1 & "'!$C:$G"), 5, FALSE),"") | J9: =IFERROR(VLOOKUP($A9,INDIRECT("'" & J$1 & "'!$C:$G"), 5, FALSE),"") | K9: =IFERROR(VLOOKUP($A9,INDIRECT("'" & K$1 & "'!$C:$G"), 5, FALSE),"") | L9: =IFERROR(VLOOKUP($A9,INDIRECT("'" & L$1 & "'!$C:$G"), 5, FALSE),"") | ... T9: =IFERROR(VLOOKUP($A9,INDIRECT("'" & T$1 & "'!$C:$G"), 5, FALSE),"") | U9: =IFERROR(__xludf.DUMMYFUNCTION("""COMPUTED_VALUE"""),"Hugo Alexander Fonseca Chaparro") -> Hugo Alexander Fonseca Chaparro | V9: =IFERROR(__xludf.DUMMYFUNCTION("""COMPUTED_VALUE"""),"Aplicación de realidad virtual para exposición gradual y controlada a espacios cerrados en personas con claustrofobia") -> Aplicación de realidad virtual para exposición gradual y controlada a espacios cerrados en personas con claustrofobia | W9: =IFERROR(__xludf.DUMMYFUNCTION("""COMPUTED_VALUE"""),"") | X9: =IFERROR(__xludf.DUMMYFUNCTION("""COMPUTED_VALUE"""),"X") -> X | Y9: =IFERROR(__xludf.DUMMYFUNCTION("""COMPUTED_VALUE"""),"X") -> X | Z9: =IFERROR(__xludf.DUMMYFUNCTION("""COMPUTED_VALUE"""),"X") -> X | AA9: =IFERROR(__xludf.DUMMYFUNCTION("""COMPUTED_VALUE"""),"") | AB9: =IFERROR(__xludf.DUMMYFUNCTION("""COMPUTED_VALUE"""),"") | AC9: =IFERROR(__xludf.DUMMYFUNCTION("""COMPUTED_VALUE"""),"") | AD9: =IFERROR(__xludf.DUMMYFUNCTION("""COMPUTED_VALUE"""),"")
A10: =IFERROR(__xludf.DUMMYFUNCTION("""COMPUTED_VALUE"""),"Sergio Andrés Rangel Montaña") -> Sergio Andrés Rangel Montaña | C10: =IF(B10="","",COUNT(E10:T10)) | D10: =IFERROR(SUM(E10:T10)/B10,"") | E10: =IFERROR(VLOOKUP($A10,INDIRECT("'" & E$1 & "'!$C:$G"), 5, FALSE),"") | F10: =IFERROR(VLOOKUP($A10,INDIRECT("'" & F$1 & "'!$C:$G"), 5, FALSE),"") | G10: =IFERROR(VLOOKUP($A10,INDIRECT("'" & G$1 & "'!$C:$G"), 5, FALSE),"") | H10: =IFERROR(VLOOKUP($A10,INDIRECT("'" & H$1 & "'!$C:$G"), 5, FALSE),"") | I10: =IFERROR(VLOOKUP($A10,INDIRECT("'" & I$1 & "'!$C:$G"), 5, FALSE),"") | J10: =IFERROR(VLOOKUP($A10,INDIRECT("'" & J$1 & "'!$C:$G"), 5, FALSE),"") | K10: =IFERROR(VLOOKUP($A10,INDIRECT("'" & K$1 & "'!$C:$G"), 5, FALSE),"") | L10: =IFERROR(VLOOKUP($A10,INDIRECT("'" & L$1 & "'!$C:$G"), 5, FALSE),"") | ... T10: =IFERROR(VLOOKUP($A10,INDIRECT("'" & T$1 & "'!$C:$G"), 5, FALSE),"") | U10: =IFERROR(__xludf.DUMMYFUNCTION("""COMPUTED_VALUE"""),"Juan Pablo Alba Martinez ") -> Juan Pablo Alba Martinez | V10: =IFERROR(__xludf.DUMMYFUNCTION("""COMPUTED_VALUE"""),"Desarrollo e implementación de un recorrido virtual 360° como estrategia para optimizar la orientación y experiencia de usuario en los escenarios deportivos de la Universidad de Boyacá, sede Tunja") -> Desarrollo e implementación de un recorrido virtual 360° como estrategia para optimizar la orientación y experiencia de usuario en los escenarios deportivos de la Universidad de Boyacá, sede Tunja | W10: =IFERROR(__xludf.DUMMYFUNCTION("""COMPUTED_VALUE"""),"") | X10: =IFERROR(__xludf.DUMMYFUNCTION("""COMPUTED_VALUE"""),"X") -> X | Y10: =IFERROR(__xludf.DUMMYFUNCTION("""COMPUTED_VALUE"""),"X") -> X | Z10: =IFERROR(__xludf.DUMMYFUNCTION("""COMPUTED_VALUE"""),"") | AA10: =IFERROR(__xludf.DUMMYFUNCTION("""COMPUTED_VALUE"""),"") | AB10: =IFERROR(__xludf.DUMMYFUNCTION("""COMPUTED_VALUE"""),"") | AC10: =IFERROR(__xludf.DUMMYFUNCTION("""COMPUTED_VALUE"""),"") | AD10: =IFERROR(__xludf.DUMMYFUNCTION("""COMPUTED_VALUE"""),"")
A11: =IFERROR(__xludf.DUMMYFUNCTION("""COMPUTED_VALUE"""),"Axel Camilo Prieto Tiria ") -> Axel Camilo Prieto Tiria | C11: =IF(B11="","",COUNT(E11:T11)) | D11: =IFERROR(SUM(E11:T11)/B11,"") | E11: =IFERROR(VLOOKUP($A11,INDIRECT("'" & E$1 & "'!$C:$G"), 5, FALSE),"") | F11: =IFERROR(VLOOKUP($A11,INDIRECT("'" & F$1 & "'!$C:$G"), 5, FALSE),"") | G11: =IFERROR(VLOOKUP($A11,INDIRECT("'" & G$1 & "'!$C:$G"), 5, FALSE),"") | H11: =IFERROR(VLOOKUP($A11,INDIRECT("'" & H$1 & "'!$C:$G"), 5, FALSE),"") | I11: =IFERROR(VLOOKUP($A11,INDIRECT("'" & I$1 & "'!$C:$G"), 5, FALSE),"") | J11: =IFERROR(VLOOKUP($A11,INDIRECT("'" & J$1 & "'!$C:$G"), 5, FALSE),"") | K11: =IFERROR(VLOOKUP($A11,INDIRECT("'" & K$1 & "'!$C:$G"), 5, FALSE),"") | L11: =IFERROR(VLOOKUP($A11,INDIRECT("'" & L$1 & "'!$C:$G"), 5, FALSE),"") | ... T11: =IFERROR(VLOOKUP($A11,INDIRECT("'" & T$1 & "'!$C:$G"), 5, FALSE),"") | U11: =IFERROR(__xludf.DUMMYFUNCTION("""COMPUTED_VALUE"""),"Sergio Andrés Rangel Montaña") -> Sergio Andrés Rangel Montaña | V11: =IFERROR(__xludf.DUMMYFUNCTION("""COMPUTED_VALUE"""),"Prototipo de videojuego 2D para recorrido virtual guiado de la Universidad de Boyacá sede Tunja") -> Prototipo de videojuego 2D para recorrido virtual guiado de la Universidad de Boyacá sede Tunja | W11: =IFERROR(__xludf.DUMMYFUNCTION("""COMPUTED_VALUE"""),"") | X11: =IFERROR(__xludf.DUMMYFUNCTION("""COMPUTED_VALUE"""),"X") -> X | Y11: =IFERROR(__xludf.DUMMYFUNCTION("""COMPUTED_VALUE"""),"X") -> X | Z11: =IFERROR(__xludf.DUMMYFUNCTION("""COMPUTED_VALUE"""),"X") -> X | AA11: =IFERROR(__xludf.DUMMYFUNCTION("""COMPUTED_VALUE"""),"") | AB11: =IFERROR(__xludf.DUMMYFUNCTION("""COMPUTED_VALUE"""),"") | AC11: =IFERROR(__xludf.DUMMYFUNCTION("""COMPUTED_VALUE"""),"") | AD11: =IFERROR(__xludf.DUMMYFUNCTION("""COMPUTED_VALUE"""),"")
A12: =IFERROR(__xludf.DUMMYFUNCTION("""COMPUTED_VALUE"""),"Luna Natalia Bejarano Castellanos") -> Luna Natalia Bejarano Castellanos | C12: =IF(B12="","",COUNT(E12:T12)) | D12: =IFERROR(SUM(E12:T12)/B12,"") | E12: =IFERROR(VLOOKUP($A12,INDIRECT("'" & E$1 & "'!$C:$G"), 5, FALSE),"") | F12: =IFERROR(VLOOKUP($A12,INDIRECT("'" & F$1 & "'!$C:$G"), 5, FALSE),"") | G12: =IFERROR(VLOOKUP($A12,INDIRECT("'" & G$1 & "'!$C:$G"), 5, FALSE),"") | H12: =IFERROR(VLOOKUP($A12,INDIRECT("'" & H$1 & "'!$C:$G"), 5, FALSE),"") | I12: =IFERROR(VLOOKUP($A12,INDIRECT("'" & I$1 & "'!$C:$G"), 5, FALSE),"") | J12: =IFERROR(VLOOKUP($A12,INDIRECT("'" & J$1 & "'!$C:$G"), 5, FALSE),"") | K12: =IFERROR(VLOOKUP($A12,INDIRECT("'" & K$1 & "'!$C:$G"), 5, FALSE),"") | L12: =IFERROR(VLOOKUP($A12,INDIRECT("'" & L$1 & "'!$C:$G"), 5, FALSE),"") | ... T12: =IFERROR(VLOOKUP($A12,INDIRECT("'" & T$1 & "'!$C:$G"), 5, FALSE),"") | U12: =IFERROR(__xludf.DUMMYFUNCTION("""COMPUTED_VALUE"""),"Axel Camilo Prieto Tiria ") -> Axel Camilo Prieto Tiria | W12: =IFERROR(__xludf.DUMMYFUNCTION("""COMPUTED_VALUE"""),"") | X12: =IFERROR(__xludf.DUMMYFUNCTION("""COMPUTED_VALUE"""),"X") -> X | Y12: =IFERROR(__xludf.DUMMYFUNCTION("""COMPUTED_VALUE"""),"X") -> X | Z12: =IFERROR(__xludf.DUMMYFUNCTION("""COMPUTED_VALUE"""),"X") -> X | AA12: =IFERROR(__xludf.DUMMYFUNCTION("""COMPUTED_VALUE"""),"") | AB12: =IFERROR(__xludf.DUMMYFUNCTION("""COMPUTED_VALUE"""),"") | AC12: =IFERROR(__xludf.DUMMYFUNCTION("""COMPUTED_VALUE"""),"") | AD12: =IFERROR(__xludf.DUMMYFUNCTION("""COMPUTED_VALUE"""),"")
A13: =IFERROR(__xludf.DUMMYFUNCTION("""COMPUTED_VALUE"""),"Yerson Leandro Ariza Chacón") -> Yerson Leandro Ariza Chacón | C13: =IF(B13="","",COUNT(E13:T13)) | D13: =IFERROR(SUM(E13:T13)/B13,"") | E13: =IFERROR(VLOOKUP($A13,INDIRECT("'" & E$1 & "'!$C:$G"), 5, FALSE),"") | F13: =IFERROR(VLOOKUP($A13,INDIRECT("'" & F$1 & "'!$C:$G"), 5, FALSE),"") | G13: =IFERROR(VLOOKUP($A13,INDIRECT("'" & G$1 & "'!$C:$G"), 5, FALSE),"") | H13: =IFERROR(VLOOKUP($A13,INDIRECT("'" & H$1 & "'!$C:$G"), 5, FALSE),"") | I13: =IFERROR(VLOOKUP($A13,INDIRECT("'" & I$1 & "'!$C:$G"), 5, FALSE),"") | J13: =IFERROR(VLOOKUP($A13,INDIRECT("'" & J$1 & "'!$C:$G"), 5, FALSE),"") | K13: =IFERROR(VLOOKUP($A13,INDIRECT("'" & K$1 & "'!$C:$G"), 5, FALSE),"") | L13: =IFERROR(VLOOKUP($A13,INDIRECT("'" & L$1 & "'!$C:$G"), 5, FALSE),"") | ... T13: =IFERROR(VLOOKUP($A13,INDIRECT("'" & T$1 & "'!$C:$G"), 5, FALSE),"") | U13: =IFERROR(__xludf.DUMMYFUNCTION("""COMPUTED_VALUE"""),"Luna Natalia Bejarano Castellanos") -> Luna Natalia Bejarano Castellanos | V13: =IFERROR(__xludf.DUMMYFUNCTION("""COMPUTED_VALUE"""),"Videojuego educativo 2D para el fortalecimiento de la lógica de programación en estudiantes de la Universidad de Boyacá") -> Videojuego educativo 2D para el fortalecimiento de la lógica de programación en estudiantes de la Universidad de Boyacá | W13: =IFERROR(__xludf.DUMMYFUNCTION("""COMPUTED_VALUE"""),"") | X13: =IFERROR(__xludf.DUMMYFUNCTION("""COMPUTED_VALUE"""),"") | Y13: =IFERROR(__xludf.DUMMYFUNCTION("""COMPUTED_VALUE"""),"") | Z13: =IFERROR(__xludf.DUMMYFUNCTION("""COMPUTED_VALUE"""),"X") -> X | AA13: =IFERROR(__xludf.DUMMYFUNCTION("""COMPUTED_VALUE"""),"") | AB13: =IFERROR(__xludf.DUMMYFUNCTION("""COMPUTED_VALUE"""),"") | AC13: =IFERROR(__xludf.DUMMYFUNCTION("""COMPUTED_VALUE"""),"") | AD13: =IFERROR(__xludf.DUMMYFUNCTION("""COMPUTED_VALUE"""),"")
C14: =IF(B14="","",COUNT(E14:T14)) | D14: =IFERROR(SUM(E14:T14)/B14,"") | E14: =IFERROR(VLOOKUP($A14,INDIRECT("'" & E$1 & "'!$C:$G"), 5, FALSE),"") | F14: =IFERROR(VLOOKUP($A14,INDIRECT("'" & F$1 & "'!$C:$G"), 5, FALSE),"") | G14: =IFERROR(VLOOKUP($A14,INDIRECT("'" & G$1 & "'!$C:$G"), 5, FALSE),"") | H14: =IFERROR(VLOOKUP($A14,INDIRECT("'" & H$1 & "'!$C:$G"), 5, FALSE),"") | I14: =IFERROR(VLOOKUP($A14,INDIRECT("'" & I$1 & "'!$C:$G"), 5, FALSE),"") | J14: =IFERROR(VLOOKUP($A14,INDIRECT("'" & J$1 & "'!$C:$G"), 5, FALSE),"") | K14: =IFERROR(VLOOKUP($A14,INDIRECT("'" & K$1 & "'!$C:$G"), 5, FALSE),"") | L14: =IFERROR(VLOOKUP($A14,INDIRECT("'" & L$1 & "'!$C:$G"), 5, FALSE),"") | ... T14: =IFERROR(VLOOKUP($A14,INDIRECT("'" & T$1 & "'!$C:$G"), 5, FALSE),"") | U14: =IFERROR(__xludf.DUMMYFUNCTION("""COMPUTED_VALUE"""),"Yerson Leandro Ariza Chacón") -> Yerson Leandro Ariza Chacón | W14: =IFERROR(__xludf.DUMMYFUNCTION("""COMPUTED_VALUE"""),"") | X14: =IFERROR(__xludf.DUMMYFUNCTION("""COMPUTED_VALUE"""),"") | Y14: =IFERROR(__xludf.DUMMYFUNCTION("""COMPUTED_VALUE"""),"") | Z14: =IFERROR(__xludf.DUMMYFUNCTION("""COMPUTED_VALUE"""),"X") -> X | AA14: =IFERROR(__xludf.DUMMYFUNCTION("""COMPUTED_VALUE"""),"") | AB14: =IFERROR(__xludf.DUMMYFUNCTION("""COMPUTED_VALUE"""),"") | AC14: =IFERROR(__xludf.DUMMYFUNCTION("""COMPUTED_VALUE"""),"") | AD14: =IFERROR(__xludf.DUMMYFUNCTION("""COMPUTED_VALUE"""),"")
C15: =IF(B15="","",COUNT(E15:T15)) | D15: =IFERROR(SUM(E15:T15)/B15,"") | E15: =IFERROR(VLOOKUP($A15,INDIRECT("'" & E$1 & "'!$C:$G"), 5, FALSE),"") | F15: =IFERROR(VLOOKUP($A15,INDIRECT("'" & F$1 & "'!$C:$G"), 5, FALSE),"") | G15: =IFERROR(VLOOKUP($A15,INDIRECT("'" & G$1 & "'!$C:$G"), 5, FALSE),"") | H15: =IFERROR(VLOOKUP($A15,INDIRECT("'" & H$1 & "'!$C:$G"), 5, FALSE),"") | I15: =IFERROR(VLOOKUP($A15,INDIRECT("'" & I$1 & "'!$C:$G"), 5, FALSE),"") | J15: =IFERROR(VLOOKUP($A15,INDIRECT("'" & J$1 & "'!$C:$G"), 5, FALSE),"") | K15: =IFERROR(VLOOKUP($A15,INDIRECT("'" & K$1 & "'!$C:$G"), 5, FALSE),"") | L15: =IFERROR(VLOOKUP($A15,INDIRECT("'" & L$1 & "'!$C:$G"), 5, FALSE),"") | ... T15: =IFERROR(VLOOKUP($A15,INDIRECT("'" & T$1 & "'!$C:$G"), 5, FALSE),"") | U15: =IFERROR(__xludf.DUMMYFUNCTION("""COMPUTED_VALUE"""),"Brandon Andres Castiblanco Costilla") -> Brandon Andres Castiblanco Costilla | V15: =IFERROR(__xludf.DUMMYFUNCTION("""COMPUTED_VALUE"""),"Prototipo de aplicación móvil con Realidad Aumentada para guía de entrenamiento en máquinas de gimnasio de la Universidad de Boyacá") -> Prototipo de aplicación móvil con Realidad Aumentada para guía de entrenamiento en máquinas de gimnasio de la Universidad de Boyacá | W15: =IFERROR(__xludf.DUMMYFUNCTION("""COMPUTED_VALUE"""),"") | X15: =IFERROR(__xludf.DUMMYFUNCTION("""COMPUTED_VALUE"""),"X") -> X | Y15: =IFERROR(__xludf.DUMMYFUNCTION("""COMPUTED_VALUE"""),"X") -> X | Z15: =IFERROR(__xludf.DUMMYFUNCTION("""COMPUTED_VALUE"""),"") | AA15: =IFERROR(__xludf.DUMMYFUNCTION("""COMPUTED_VALUE"""),"") | AB15: =IFERROR(__xludf.DUMMYFUNCTION("""COMPUTED_VALUE"""),"") | AC15: =IFERROR(__xludf.DUMMYFUNCTION("""COMPUTED_VALUE"""),"") | AD15: =IFERROR(__xludf.DUMMYFUNCTION("""COMPUTED_VALUE"""),"")
C16: =IF(B16="","",COUNT(E16:T16)) | D16: =IFERROR(SUM(E16:T16)/B16,"") | E16: =IFERROR(VLOOKUP($A16,INDIRECT("'" & E$1 & "'!$C:$G"), 5, FALSE),"") | F16: =IFERROR(VLOOKUP($A16,INDIRECT("'" & F$1 & "'!$C:$G"), 5, FALSE),"") | G16: =IFERROR(VLOOKUP($A16,INDIRECT("'" & G$1 & "'!$C:$G"), 5, FALSE),"") | H16: =IFERROR(VLOOKUP($A16,INDIRECT("'" & H$1 & "'!$C:$G"), 5, FALSE),"") | I16: =IFERROR(VLOOKUP($A16,INDIRECT("'" & I$1 & "'!$C:$G"), 5, FALSE),"") | J16: =IFERROR(VLOOKUP($A16,INDIRECT("'" & J$1 & "'!$C:$G"), 5, FALSE),"") | K16: =IFERROR(VLOOKUP($A16,INDIRECT("'" & K$1 & "'!$C:$G"), 5, FALSE),"") | L16: =IFERROR(VLOOKUP($A16,INDIRECT("'" & L$1 & "'!$C:$G"), 5, FALSE),"") | ... T16: =IFERROR(VLOOKUP($A16,INDIRECT("'" & T$1 & "'!$C:$G"), 5, FALSE),"") | U16: =IFERROR(__xludf.DUMMYFUNCTION("""COMPUTED_VALUE"""),"Paula Andrea Ortegón Lezama") -> Paula Andrea Ortegón Lezama | V16: =IFERROR(__xludf.DUMMYFUNCTION("""COMPUTED_VALUE"""),"Videojuego como herramienta de aprendizaje del tema de balanceo de ecuaciones químicas por método de tanteo") -> Videojuego como herramienta de aprendizaje del tema de balanceo de ecuaciones químicas por método de tanteo | W16: =IFERROR(__xludf.DUMMYFUNCTION("""COMPUTED_VALUE"""),"") | X16: =IFERROR(__xludf.DUMMYFUNCTION("""COMPUTED_VALUE"""),"X") -> X | Y16: =IFERROR(__xludf.DUMMYFUNCTION("""COMPUTED_VALUE"""),"X") -> X | Z16: =IFERROR(__xludf.DUMMYFUNCTION("""COMPUTED_VALUE"""),"") | AA16: =IFERROR(__xludf.DUMMYFUNCTION("""COMPUTED_VALUE"""),"") | AB16: =IFERROR(__xludf.DUMMYFUNCTION("""COMPUTED_VALUE"""),"") | AC16: =IFERROR(__xludf.DUMMYFUNCTION("""COMPUTED_VALUE"""),"") | AD16: =IFERROR(__xludf.DUMMYFUNCTION("""COMPUTED_VALUE"""),"")
C17: =IF(B17="","",COUNT(E17:T17)) | D17: =IFERROR(SUM(E17:T17)/B17,"") | E17: =IFERROR(VLOOKUP($A17,INDIRECT("'" & E$1 & "'!$C:$G"), 5, FALSE),"") | F17: =IFERROR(VLOOKUP($A17,INDIRECT("'" & F$1 & "'!$C:$G"), 5, FALSE),"") | G17: =IFERROR(VLOOKUP($A17,INDIRECT("'" & G$1 & "'!$C:$G"), 5, FALSE),"") | H17: =IFERROR(VLOOKUP($A17,INDIRECT("'" & H$1 & "'!$C:$G"), 5, FALSE),"") | I17: =IFERROR(VLOOKUP($A17,INDIRECT("'" & I$1 & "'!$C:$G"), 5, FALSE),"") | J17: =IFERROR(VLOOKUP($A17,INDIRECT("'" & J$1 & "'!$C:$G"), 5, FALSE),"") | K17: =IFERROR(VLOOKUP($A17,INDIRECT("'" & K$1 & "'!$C:$G"), 5, FALSE),"") | L17: =IFERROR(VLOOKUP($A17,INDIRECT("'" & L$1 & "'!$C:$G"), 5, FALSE),"") | ... T17: =IFERROR(VLOOKUP($A17,INDIRECT("'" & T$1 & "'!$C:$G"), 5, FALSE),"") | U17: =IFERROR(__xludf.DUMMYFUNCTION("""COMPUTED_VALUE"""),"Juan Sebastian Sanabria Mendivelso") -> Juan Sebastian Sanabria Mendivelso | W17: =IFERROR(__xludf.DUMMYFUNCTION("""COMPUTED_VALUE"""),"") | X17: =IFERROR(__xludf.DUMMYFUNCTION("""COMPUTED_VALUE"""),"X") -> X | Y17: =IFERROR(__xludf.DUMMYFUNCTION("""COMPUTED_VALUE"""),"X") -> X | Z17: =IFERROR(__xludf.DUMMYFUNCTION("""COMPUTED_VALUE"""),"") | AA17: =IFERROR(__xludf.DUMMYFUNCTION("""COMPUTED_VALUE"""),"") | AB17: =IFERROR(__xludf.DUMMYFUNCTION("""COMPUTED_VALUE"""),"") | AC17: =IFERROR(__xludf.DUMMYFUNCTION("""COMPUTED_VALUE"""),"") | AD17: =IFERROR(__xludf.DUMMYFUNCTION("""COMPUTED_VALUE"""),"")
C18: =IF(B18="","",COUNT(E18:T18)) | D18: =IFERROR(SUM(E18:T18)/B18,"") | E18: =IFERROR(VLOOKUP($A18,INDIRECT("'" & E$1 & "'!$C:$G"), 5, FALSE),"") | F18: =IFERROR(VLOOKUP($A18,INDIRECT("'" & F$1 & "'!$C:$G"), 5, FALSE),"") | G18: =IFERROR(VLOOKUP($A18,INDIRECT("'" & G$1 & "'!$C:$G"), 5, FALSE),"") | H18: =IFERROR(VLOOKUP($A18,INDIRECT("'" & H$1 & "'!$C:$G"), 5, FALSE),"") | I18: =IFERROR(VLOOKUP($A18,INDIRECT("'" & I$1 & "'!$C:$G"), 5, FALSE),"") | J18: =IFERROR(VLOOKUP($A18,INDIRECT("'" & J$1 & "'!$C:$G"), 5, FALSE),"") | K18: =IFERROR(VLOOKUP($A18,INDIRECT("'" & K$1 & "'!$C:$G"), 5, FALSE),"") | L18: =IFERROR(VLOOKUP($A18,INDIRECT("'" & L$1 & "'!$C:$G"), 5, FALSE),"") | ... T18: =IFERROR(VLOOKUP($A18,INDIRECT("'" & T$1 & "'!$C:$G"), 5, FALSE),"") | U18: =IFERROR(__xludf.DUMMYFUNCTION("""COMPUTED_VALUE"""),"Diana Patricia Acuña Cardozo ") -> Diana Patricia Acuña Cardozo | V18: =IFERROR(__xludf.DUMMYFUNCTION("""COMPUTED_VALUE"""),"Prototipo de videojuego para divulgar el Puente de Boyacá") -> Prototipo de videojuego para divulgar el Puente de Boyacá | W18: =IFERROR(__xludf.DUMMYFUNCTION("""COMPUTED_VALUE"""),"") | X18: =IFERROR(__xludf.DUMMYFUNCTION("""COMPUTED_VALUE"""),"X") -> X | Y18: =IFERROR(__xludf.DUMMYFUNCTION("""COMPUTED_VALUE"""),"") | Z18: =IFERROR(__xludf.DUMMYFUNCTION("""COMPUTED_VALUE"""),"") | AA18: =IFERROR(__xludf.DUMMYFUNCTION("""COMPUTED_VALUE"""),"") | AB18: =IFERROR(__xludf.DUMMYFUNCTION("""COMPUTED_VALUE"""),"") | AC18: =IFERROR(__xludf.DUMMYFUNCTION("""COMPUTED_VALUE"""),"") | AD18: =IFERROR(__xludf.DUMMYFUNCTION("""COMPUTED_VALUE"""),"")
C19: =IF(B19="","",COUNT(E19:T19)) | D19: =IFERROR(SUM(E19:T19)/B19,"") | E19: =IFERROR(VLOOKUP($A19,INDIRECT("'" & E$1 & "'!$C:$G"), 5, FALSE),"") | F19: =IFERROR(VLOOKUP($A19,INDIRECT("'" & F$1 & "'!$C:$G"), 5, FALSE),"") | G19: =IFERROR(VLOOKUP($A19,INDIRECT("'" & G$1 & "'!$C:$G"), 5, FALSE),"") | H19: =IFERROR(VLOOKUP($A19,INDIRECT("'" & H$1 & "'!$C:$G"), 5, FALSE),"") | I19: =IFERROR(VLOOKUP($A19,INDIRECT("'" & I$1 & "'!$C:$G"), 5, FALSE),"") | J19: =IFERROR(VLOOKUP($A19,INDIRECT("'" & J$1 & "'!$C:$G"), 5, FALSE),"") | K19: =IFERROR(VLOOKUP($A19,INDIRECT("'" & K$1 & "'!$C:$G"), 5, FALSE),"") | L19: =IFERROR(VLOOKUP($A19,INDIRECT("'" & L$1 & "'!$C:$G"), 5, FALSE),"") | ... T19: =IFERROR(VLOOKUP($A19,INDIRECT("'" & T$1 & "'!$C:$G"), 5, FALSE),"") | V19: =IFERROR(__xludf.DUMMYFUNCTION("""COMPUTED_VALUE"""),"") | W19: =IFERROR(__xludf.DUMMYFUNCTION("""COMPUTED_VALUE"""),"") | X19: =IFERROR(__xludf.DUMMYFUNCTION("""COMPUTED_VALUE"""),"") | Y19: =IFERROR(__xludf.DUMMYFUNCTION("""COMPUTED_VALUE"""),"") | Z19: =IFERROR(__xludf.DUMMYFUNCTION("""COMPUTED_VALUE"""),"") | AA19: =IFERROR(__xludf.DUMMYFUNCTION("""COMPUTED_VALUE"""),"") | AB19: =IFERROR(__xludf.DUMMYFUNCTION("""COMPUTED_VALUE"""),"") | AC19: =IFERROR(__xludf.DUMMYFUNCTION("""COMPUTED_VALUE"""),"") | AD19: =IFERROR(__xludf.DUMMYFUNCTION("""COMPUTED_VALUE"""),"")
C20: =IF(B20="","",COUNT(E20:T20)) | D20: =IFERROR(SUM(E20:T20)/B20,"") | E20: =IFERROR(VLOOKUP($A20,INDIRECT("'" & E$1 & "'!$C:$G"), 5, FALSE),"") | F20: =IFERROR(VLOOKUP($A20,INDIRECT("'" & F$1 & "'!$C:$G"), 5, FALSE),"") | G20: =IFERROR(VLOOKUP($A20,INDIRECT("'" & G$1 & "'!$C:$G"), 5, FALSE),"") | H20: =IFERROR(VLOOKUP($A20,INDIRECT("'" & H$1 & "'!$C:$G"), 5, FALSE),"") | I20: =IFERROR(VLOOKUP($A20,INDIRECT("'" & I$1 & "'!$C:$G"), 5, FALSE),"") | J20: =IFERROR(VLOOKUP($A20,INDIRECT("'" & J$1 & "'!$C:$G"), 5, FALSE),"") | K20: =IFERROR(VLOOKUP($A20,INDIRECT("'" & K$1 & "'!$C:$G"), 5, FALSE),"") | L20: =IFERROR(VLOOKUP($A20,INDIRECT("'" & L$1 & "'!$C:$G"), 5, FALSE),"") | ... T20: =IFERROR(VLOOKUP($A20,INDIRECT("'" & T$1 & "'!$C:$G"), 5, FALSE),"") | V20: =IFERROR(__xludf.DUMMYFUNCTION("""COMPUTED_VALUE"""),"") | W20: =IFERROR(__xludf.DUMMYFUNCTION("""COMPUTED_VALUE"""),"") | X20: =IFERROR(__xludf.DUMMYFUNCTION("""COMPUTED_VALUE"""),"") | Y20: =IFERROR(__xludf.DUMMYFUNCTION("""COMPUTED_VALUE"""),"") | Z20: =IFERROR(__xludf.DUMMYFUNCTION("""COMPUTED_VALUE"""),"") | AA20: =IFERROR(__xludf.DUMMYFUNCTION("""COMPUTED_VALUE"""),"") | AB20: =IFERROR(__xludf.DUMMYFUNCTION("""COMPUTED_VALUE"""),"") | AC20: =IFERROR(__xludf.DUMMYFUNCTION("""COMPUTED_VALUE"""),"") | AD20: =IFERROR(__xludf.DUMMYFUNCTION("""COMPUTED_VALUE"""),"")
C21: =IF(B21="","",COUNT(E21:T21)) | D21: =IFERROR(SUM(E21:T21)/B21,"") | E21: =IFERROR(VLOOKUP($A21,INDIRECT("'" & E$1 & "'!$C:$G"), 5, FALSE),"") | F21: =IFERROR(VLOOKUP($A21,INDIRECT("'" & F$1 & "'!$C:$G"), 5, FALSE),"") | G21: =IFERROR(VLOOKUP($A21,INDIRECT("'" & G$1 & "'!$C:$G"), 5, FALSE),"") | H21: =IFERROR(VLOOKUP($A21,INDIRECT("'" & H$1 & "'!$C:$G"), 5, FALSE),"") | I21: =IFERROR(VLOOKUP($A21,INDIRECT("'" & I$1 & "'!$C:$G"), 5, FALSE),"") | J21: =IFERROR(VLOOKUP($A21,INDIRECT("'" & J$1 & "'!$C:$G"), 5, FALSE),"") | K21: =IFERROR(VLOOKUP($A21,INDIRECT("'" & K$1 & "'!$C:$G"), 5, FALSE),"") | L21: =IFERROR(VLOOKUP($A21,INDIRECT("'" & L$1 & "'!$C:$G"), 5, FALSE),"") | ... T21: =IFERROR(VLOOKUP($A21,INDIRECT("'" & T$1 & "'!$C:$G"), 5, FALSE),"") | V21: =IFERROR(__xludf.DUMMYFUNCTION("""COMPUTED_VALUE"""),"") | W21: =IFERROR(__xludf.DUMMYFUNCTION("""COMPUTED_VALUE"""),"") | X21: =IFERROR(__xludf.DUMMYFUNCTION("""COMPUTED_VALUE"""),"") | Y21: =IFERROR(__xludf.DUMMYFUNCTION("""COMPUTED_VALUE"""),"") | Z21: =IFERROR(__xludf.DUMMYFUNCTION("""COMPUTED_VALUE"""),"") | AA21: =IFERROR(__xludf.DUMMYFUNCTION("""COMPUTED_VALUE"""),"") | AB21: =IFERROR(__xludf.DUMMYFUNCTION("""COMPUTED_VALUE"""),"") | AC21: =IFERROR(__xludf.DUMMYFUNCTION("""COMPUTED_VALUE"""),"") | AD21: =IFERROR(__xludf.DUMMYFUNCTION("""COMPUTED_VALUE"""),"")
C22: =IF(B22="","",COUNT(E22:T22)) | D22: =IFERROR(SUM(E22:T22)/B22,"") | E22: =IFERROR(VLOOKUP($A22,INDIRECT("'" & E$1 & "'!$C:$G"), 5, FALSE),"") | F22: =IFERROR(VLOOKUP($A22,INDIRECT("'" & F$1 & "'!$C:$G"), 5, FALSE),"") | G22: =IFERROR(VLOOKUP($A22,INDIRECT("'" & G$1 & "'!$C:$G"), 5, FALSE),"") | H22: =IFERROR(VLOOKUP($A22,INDIRECT("'" & H$1 & "'!$C:$G"), 5, FALSE),"") | I22: =IFERROR(VLOOKUP($A22,INDIRECT("'" & I$1 & "'!$C:$G"), 5, FALSE),"") | J22: =IFERROR(VLOOKUP($A22,INDIRECT("'" & J$1 & "'!$C:$G"), 5, FALSE),"") | K22: =IFERROR(VLOOKUP($A22,INDIRECT("'" & K$1 & "'!$C:$G"), 5, FALSE),"") | L22: =IFERROR(VLOOKUP($A22,INDIRECT("'" & L$1 & "'!$C:$G"), 5, FALSE),"") | ... T22: =IFERROR(VLOOKUP($A22,INDIRECT("'" & T$1 & "'!$C:$G"), 5, FALSE),"") | V22: =IFERROR(__xludf.DUMMYFUNCTION("""COMPUTED_VALUE"""),"") | W22: =IFERROR(__xludf.DUMMYFUNCTION("""COMPUTED_VALUE"""),"") | X22: =IFERROR(__xludf.DUMMYFUNCTION("""COMPUTED_VALUE"""),"") | Y22: =IFERROR(__xludf.DUMMYFUNCTION("""COMPUTED_VALUE"""),"") | Z22: =IFERROR(__xludf.DUMMYFUNCTION("""COMPUTED_VALUE"""),"") | AA22: =IFERROR(__xludf.DUMMYFUNCTION("""COMPUTED_VALUE"""),"") | AB22: =IFERROR(__xludf.DUMMYFUNCTION("""COMPUTED_VALUE"""),"") | AC22: =IFERROR(__xludf.DUMMYFUNCTION("""COMPUTED_VALUE"""),"") | AD22: =IFERROR(__xludf.DUMMYFUNCTION("""COMPUTED_VALUE"""),"")
C23: =IF(B23="","",COUNT(E23:T23)) | D23: =IFERROR(SUM(E23:T23)/B23,"") | E23: =IFERROR(VLOOKUP($A23,INDIRECT("'" & E$1 & "'!$C:$G"), 5, FALSE),"") | F23: =IFERROR(VLOOKUP($A23,INDIRECT("'" & F$1 & "'!$C:$G"), 5, FALSE),"") | G23: =IFERROR(VLOOKUP($A23,INDIRECT("'" & G$1 & "'!$C:$G"), 5, FALSE),"") | H23: =IFERROR(VLOOKUP($A23,INDIRECT("'" & H$1 & "'!$C:$G"), 5, FALSE),"") | I23: =IFERROR(VLOOKUP($A23,INDIRECT("'" & I$1 & "'!$C:$G"), 5, FALSE),"") | J23: =IFERROR(VLOOKUP($A23,INDIRECT("'" & J$1 & "'!$C:$G"), 5, FALSE),"") | K23: =IFERROR(VLOOKUP($A23,INDIRECT("'" & K$1 & "'!$C:$G"), 5, FALSE),"") | L23: =IFERROR(VLOOKUP($A23,INDIRECT("'" & L$1 & "'!$C:$G"), 5, FALSE),"") | ... T23: =IFERROR(VLOOKUP($A23,INDIRECT("'" & T$1 & "'!$C:$G"), 5, FALSE),"") | V23: =IFERROR(__xludf.DUMMYFUNCTION("""COMPUTED_VALUE"""),"") | W23: =IFERROR(__xludf.DUMMYFUNCTION("""COMPUTED_VALUE"""),"") | X23: =IFERROR(__xludf.DUMMYFUNCTION("""COMPUTED_VALUE"""),"") | Y23: =IFERROR(__xludf.DUMMYFUNCTION("""COMPUTED_VALUE"""),"") | Z23: =IFERROR(__xludf.DUMMYFUNCTION("""COMPUTED_VALUE"""),"") | AA23: =IFERROR(__xludf.DUMMYFUNCTION("""COMPUTED_VALUE"""),"") | AB23: =IFERROR(__xludf.DUMMYFUNCTION("""COMPUTED_VALUE"""),"") | AC23: =IFERROR(__xludf.DUMMYFUNCTION("""COMPUTED_VALUE"""),"") | AD23: =IFERROR(__xludf.DUMMYFUNCTION("""COMPUTED_VALUE"""),"")
C24: =IF(B24="","",COUNT(E24:T24)) | D24: =IFERROR(SUM(E24:T24)/B24,"") | E24: =IFERROR(VLOOKUP($A24,INDIRECT("'" & E$1 & "'!$C:$G"), 5, FALSE),"") | F24: =IFERROR(VLOOKUP($A24,INDIRECT("'" & F$1 & "'!$C:$G"), 5, FALSE),"") | G24: =IFERROR(VLOOKUP($A24,INDIRECT("'" & G$1 & "'!$C:$G"), 5, FALSE),"") | H24: =IFERROR(VLOOKUP($A24,INDIRECT("'" & H$1 & "'!$C:$G"), 5, FALSE),"") | I24: =IFERROR(VLOOKUP($A24,INDIRECT("'" & I$1 & "'!$C:$G"), 5, FALSE),"") | J24: =IFERROR(VLOOKUP($A24,INDIRECT("'" & J$1 & "'!$C:$G"), 5, FALSE),"") | K24: =IFERROR(VLOOKUP($A24,INDIRECT("'" & K$1 & "'!$C:$G"), 5, FALSE),"") | L24: =IFERROR(VLOOKUP($A24,INDIRECT("'" & L$1 & "'!$C:$G"), 5, FALSE),"") | ... T24: =IFERROR(VLOOKUP($A24,INDIRECT("'" & T$1 & "'!$C:$G"), 5, FALSE),"") | V24: =IFERROR(__xludf.DUMMYFUNCTION("""COMPUTED_VALUE"""),"") | W24: =IFERROR(__xludf.DUMMYFUNCTION("""COMPUTED_VALUE"""),"") | X24: =IFERROR(__xludf.DUMMYFUNCTION("""COMPUTED_VALUE"""),"") | Y24: =IFERROR(__xludf.DUMMYFUNCTION("""COMPUTED_VALUE"""),"") | Z24: =IFERROR(__xludf.DUMMYFUNCTION("""COMPUTED_VALUE"""),"") | AA24: =IFERROR(__xludf.DUMMYFUNCTION("""COMPUTED_VALUE"""),"") | AB24: =IFERROR(__xludf.DUMMYFUNCTION("""COMPUTED_VALUE"""),"") | AC24: =IFERROR(__xludf.DUMMYFUNCTION("""COMPUTED_VALUE"""),"") | AD24: =IFERROR(__xludf.DUMMYFUNCTION("""COMPUTED_VALUE"""),"")
C25: =IF(B25="","",COUNT(E25:T25)) | D25: =IFERROR(SUM(E25:T25)/B25,"") | E25: =IFERROR(VLOOKUP($A25,INDIRECT("'" & E$1 & "'!$C:$G"), 5, FALSE),"") | F25: =IFERROR(VLOOKUP($A25,INDIRECT("'" & F$1 & "'!$C:$G"), 5, FALSE),"") | G25: =IFERROR(VLOOKUP($A25,INDIRECT("'" & G$1 & "'!$C:$G"), 5, FALSE),"") | H25: =IFERROR(VLOOKUP($A25,INDIRECT("'" & H$1 & "'!$C:$G"), 5, FALSE),"") | I25: =IFERROR(VLOOKUP($A25,INDIRECT("'" & I$1 & "'!$C:$G"), 5, FALSE),"") | J25: =IFERROR(VLOOKUP($A25,INDIRECT("'" & J$1 & "'!$C:$G"), 5, FALSE),"") | K25: =IFERROR(VLOOKUP($A25,INDIRECT("'" & K$1 & "'!$C:$G"), 5, FALSE),"") | L25: =IFERROR(VLOOKUP($A25,INDIRECT("'" & L$1 & "'!$C:$G"), 5, FALSE),"") | ... T25: =IFERROR(VLOOKUP($A25,INDIRECT("'" & T$1 & "'!$C:$G"), 5, FALSE),"") | V25: =IFERROR(__xludf.DUMMYFUNCTION("""COMPUTED_VALUE"""),"") | W25: =IFERROR(__xludf.DUMMYFUNCTION("""COMPUTED_VALUE"""),"") | X25: =IFERROR(__xludf.DUMMYFUNCTION("""COMPUTED_VALUE"""),"") | Y25: =IFERROR(__xludf.DUMMYFUNCTION("""COMPUTED_VALUE"""),"") | Z25: =IFERROR(__xludf.DUMMYFUNCTION("""COMPUTED_VALUE"""),"") | AA25: =IFERROR(__xludf.DUMMYFUNCTION("""COMPUTED_VALUE"""),"") | AB25: =IFERROR(__xludf.DUMMYFUNCTION("""COMPUTED_VALUE"""),"") | AC25: =IFERROR(__xludf.DUMMYFUNCTION("""COMPUTED_VALUE"""),"") | AD25: =IFERROR(__xludf.DUMMYFUNCTION("""COMPUTED_VALUE"""),"")
C26: =IF(B26="","",COUNT(E26:T26)) | D26: =IFERROR(SUM(E26:T26)/B26,"") | E26: =IFERROR(VLOOKUP($A26,INDIRECT("'" & E$1 & "'!$C:$G"), 5, FALSE),"") | F26: =IFERROR(VLOOKUP($A26,INDIRECT("'" & F$1 & "'!$C:$G"), 5, FALSE),"") | G26: =IFERROR(VLOOKUP($A26,INDIRECT("'" & G$1 & "'!$C:$G"), 5, FALSE),"") | H26: =IFERROR(VLOOKUP($A26,INDIRECT("'" & H$1 & "'!$C:$G"), 5, FALSE),"") | I26: =IFERROR(VLOOKUP($A26,INDIRECT("'" & I$1 & "'!$C:$G"), 5, FALSE),"") | J26: =IFERROR(VLOOKUP($A26,INDIRECT("'" & J$1 & "'!$C:$G"), 5, FALSE),"") | K26: =IFERROR(VLOOKUP($A26,INDIRECT("'" & K$1 & "'!$C:$G"), 5, FALSE),"") | L26: =IFERROR(VLOOKUP($A26,INDIRECT("'" & L$1 & "'!$C:$G"), 5, FALSE),"") | ... T26: =IFERROR(VLOOKUP($A26,INDIRECT("'" & T$1 & "'!$C:$G"), 5, FALSE),"") | V26: =IFERROR(__xludf.DUMMYFUNCTION("""COMPUTED_VALUE"""),"") | W26: =IFERROR(__xludf.DUMMYFUNCTION("""COMPUTED_VALUE"""),"") | X26: =IFERROR(__xludf.DUMMYFUNCTION("""COMPUTED_VALUE"""),"") | Y26: =IFERROR(__xludf.DUMMYFUNCTION("""COMPUTED_VALUE"""),"") | Z26: =IFERROR(__xludf.DUMMYFUNCTION("""COMPUTED_VALUE"""),"") | AA26: =IFERROR(__xludf.DUMMYFUNCTION("""COMPUTED_VALUE"""),"") | AB26: =IFERROR(__xludf.DUMMYFUNCTION("""COMPUTED_VALUE"""),"") | AC26: =IFERROR(__xludf.DUMMYFUNCTION("""COMPUTED_VALUE"""),"") | AD26: =IFERROR(__xludf.DUMMYFUNCTION("""COMPUTED_VALUE"""),"")
C27: =IF(B27="","",COUNT(E27:T27)) | D27: =IFERROR(SUM(E27:T27)/B27,"") | E27: =IFERROR(VLOOKUP($A27,INDIRECT("'" & E$1 & "'!$C:$G"), 5, FALSE),"") | F27: =IFERROR(VLOOKUP($A27,INDIRECT("'" & F$1 & "'!$C:$G"), 5, FALSE),"") | G27: =IFERROR(VLOOKUP($A27,INDIRECT("'" & G$1 & "'!$C:$G"), 5, FALSE),"") | H27: =IFERROR(VLOOKUP($A27,INDIRECT("'" & H$1 & "'!$C:$G"), 5, FALSE),"") | I27: =IFERROR(VLOOKUP($A27,INDIRECT("'" & I$1 & "'!$C:$G"), 5, FALSE),"") | J27: =IFERROR(VLOOKUP($A27,INDIRECT("'" & J$1 & "'!$C:$G"), 5, FALSE),"") | K27: =IFERROR(VLOOKUP($A27,INDIRECT("'" & K$1 & "'!$C:$G"), 5, FALSE),"") | L27: =IFERROR(VLOOKUP($A27,INDIRECT("'" & L$1 & "'!$C:$G"), 5, FALSE),"") | ... T27: =IFERROR(VLOOKUP($A27,INDIRECT("'" & T$1 & "'!$C:$G"), 5, FALSE),"") | V27: =IFERROR(__xludf.DUMMYFUNCTION("""COMPUTED_VALUE"""),"") | W27: =IFERROR(__xludf.DUMMYFUNCTION("""COMPUTED_VALUE"""),"") | X27: =IFERROR(__xludf.DUMMYFUNCTION("""COMPUTED_VALUE"""),"") | Y27: =IFERROR(__xludf.DUMMYFUNCTION("""COMPUTED_VALUE"""),"") | Z27: =IFERROR(__xludf.DUMMYFUNCTION("""COMPUTED_VALUE"""),"") | AA27: =IFERROR(__xludf.DUMMYFUNCTION("""COMPUTED_VALUE"""),"") | AB27: =IFERROR(__xludf.DUMMYFUNCTION("""COMPUTED_VALUE"""),"") | AC27: =IFERROR(__xludf.DUMMYFUNCTION("""COMPUTED_VALUE"""),"") | AD27: =IFERROR(__xludf.DUMMYFUNCTION("""COMPUTED_VALUE"""),"")
C28: =IF(B28="","",COUNT(E28:T28)) | D28: =IFERROR(SUM(E28:T28)/B28,"") | E28: =IFERROR(VLOOKUP($A28,INDIRECT("'" & E$1 & "'!$C:$G"), 5, FALSE),"") | F28: =IFERROR(VLOOKUP($A28,INDIRECT("'" & F$1 & "'!$C:$G"), 5, FALSE),"") | G28: =IFERROR(VLOOKUP($A28,INDIRECT("'" & G$1 & "'!$C:$G"), 5, FALSE),"") | H28: =IFERROR(VLOOKUP($A28,INDIRECT("'" & H$1 & "'!$C:$G"), 5, FALSE),"") | I28: =IFERROR(VLOOKUP($A28,INDIRECT("'" & I$1 & "'!$C:$G"), 5, FALSE),"") | J28: =IFERROR(VLOOKUP($A28,INDIRECT("'" & J$1 & "'!$C:$G"), 5, FALSE),"") | K28: =IFERROR(VLOOKUP($A28,INDIRECT("'" & K$1 & "'!$C:$G"), 5, FALSE),"") | L28: =IFERROR(VLOOKUP($A28,INDIRECT("'" & L$1 & "'!$C:$G"), 5, FALSE),"") | ... T28: =IFERROR(VLOOKUP($A28,INDIRECT("'" & T$1 & "'!$C:$G"), 5, FALSE),"") | V28: =IFERROR(__xludf.DUMMYFUNCTION("""COMPUTED_VALUE"""),"") | W28: =IFERROR(__xludf.DUMMYFUNCTION("""COMPUTED_VALUE"""),"") | X28: =IFERROR(__xludf.DUMMYFUNCTION("""COMPUTED_VALUE"""),"") | Y28: =IFERROR(__xludf.DUMMYFUNCTION("""COMPUTED_VALUE"""),"") | Z28: =IFERROR(__xludf.DUMMYFUNCTION("""COMPUTED_VALUE"""),"") | AA28: =IFERROR(__xludf.DUMMYFUNCTION("""COMPUTED_VALUE"""),"") | AB28: =IFERROR(__xludf.DUMMYFUNCTION("""COMPUTED_VALUE"""),"") | AC28: =IFERROR(__xludf.DUMMYFUNCTION("""COMPUTED_VALUE"""),"") | AD28: =IFERROR(__xludf.DUMMYFUNCTION("""COMPUTED_VALUE"""),"")
C29: =IF(B29="","",COUNT(E29:T29)) | D29: =IFERROR(SUM(E29:T29)/B29,"") | E29: =IFERROR(VLOOKUP($A29,INDIRECT("'" & E$1 & "'!$C:$G"), 5, FALSE),"") | F29: =IFERROR(VLOOKUP($A29,INDIRECT("'" & F$1 & "'!$C:$G"), 5, FALSE),"") | G29: =IFERROR(VLOOKUP($A29,INDIRECT("'" & G$1 & "'!$C:$G"), 5, FALSE),"") | H29: =IFERROR(VLOOKUP($A29,INDIRECT("'" & H$1 & "'!$C:$G"), 5, FALSE),"") | I29: =IFERROR(VLOOKUP($A29,INDIRECT("'" & I$1 & "'!$C:$G"), 5, FALSE),"") | J29: =IFERROR(VLOOKUP($A29,INDIRECT("'" & J$1 & "'!$C:$G"), 5, FALSE),"") | K29: =IFERROR(VLOOKUP($A29,INDIRECT("'" & K$1 & "'!$C:$G"), 5, FALSE),"") | L29: =IFERROR(VLOOKUP($A29,INDIRECT("'" & L$1 & "'!$C:$G"), 5, FALSE),"") | ... T29: =IFERROR(VLOOKUP($A29,INDIRECT("'" & T$1 & "'!$C:$G"), 5, FALSE),"") | V29: =IFERROR(__xludf.DUMMYFUNCTION("""COMPUTED_VALUE"""),"") | W29: =IFERROR(__xludf.DUMMYFUNCTION("""COMPUTED_VALUE"""),"") | X29: =IFERROR(__xludf.DUMMYFUNCTION("""COMPUTED_VALUE"""),"") | Y29: =IFERROR(__xludf.DUMMYFUNCTION("""COMPUTED_VALUE"""),"") | Z29: =IFERROR(__xludf.DUMMYFUNCTION("""COMPUTED_VALUE"""),"") | AA29: =IFERROR(__xludf.DUMMYFUNCTION("""COMPUTED_VALUE"""),"") | AB29: =IFERROR(__xludf.DUMMYFUNCTION("""COMPUTED_VALUE"""),"") | AC29: =IFERROR(__xludf.DUMMYFUNCTION("""COMPUTED_VALUE"""),"") | AD29: =IFERROR(__xludf.DUMMYFUNCTION("""COMPUTED_VALUE"""),"")
C30: =IF(B30="","",COUNT(E30:T30)) | D30: =IFERROR(SUM(E30:T30)/B30,"") | E30: =IFERROR(VLOOKUP($A30,INDIRECT("'" & E$1 & "'!$C:$G"), 5, FALSE),"") | F30: =IFERROR(VLOOKUP($A30,INDIRECT("'" & F$1 & "'!$C:$G"), 5, FALSE),"") | G30: =IFERROR(VLOOKUP($A30,INDIRECT("'" & G$1 & "'!$C:$G"), 5, FALSE),"") | H30: =IFERROR(VLOOKUP($A30,INDIRECT("'" & H$1 & "'!$C:$G"), 5, FALSE),"") | I30: =IFERROR(VLOOKUP($A30,INDIRECT("'" & I$1 & "'!$C:$G"), 5, FALSE),"") | J30: =IFERROR(VLOOKUP($A30,INDIRECT("'" & J$1 & "'!$C:$G"), 5, FALSE),"") | K30: =IFERROR(VLOOKUP($A30,INDIRECT("'" & K$1 & "'!$C:$G"), 5, FALSE),"") | L30: =IFERROR(VLOOKUP($A30,INDIRECT("'" & L$1 & "'!$C:$G"), 5, FALSE),"") | ... T30: =IFERROR(VLOOKUP($A30,INDIRECT("'" & T$1 & "'!$C:$G"), 5, FALSE),"") | V30: =IFERROR(__xludf.DUMMYFUNCTION("""COMPUTED_VALUE"""),"") | W30: =IFERROR(__xludf.DUMMYFUNCTION("""COMPUTED_VALUE"""),"") | X30: =IFERROR(__xludf.DUMMYFUNCTION("""COMPUTED_VALUE"""),"") | Y30: =IFERROR(__xludf.DUMMYFUNCTION("""COMPUTED_VALUE"""),"") | Z30: =IFERROR(__xludf.DUMMYFUNCTION("""COMPUTED_VALUE"""),"") | AA30: =IFERROR(__xludf.DUMMYFUNCTION("""COMPUTED_VALUE"""),"") | AB30: =IFERROR(__xludf.DUMMYFUNCTION("""COMPUTED_VALUE"""),"") | AC30: =IFERROR(__xludf.DUMMYFUNCTION("""COMPUTED_VALUE"""),"") | AD30: =IFERROR(__xludf.DUMMYFUNCTION("""COMPUTED_VALUE"""),"")
